{
  "nbformat": 4,
  "nbformat_minor": 0,
  "metadata": {
    "colab": {
      "provenance": [],
      "authorship_tag": "ABX9TyM80FVMsdkOb5BlLVDXUA7x",
      "include_colab_link": true
    },
    "kernelspec": {
      "name": "python3",
      "display_name": "Python 3"
    },
    "language_info": {
      "name": "python"
    }
  },
  "cells": [
    {
      "cell_type": "markdown",
      "metadata": {
        "id": "view-in-github",
        "colab_type": "text"
      },
      "source": [
        "<a href=\"https://colab.research.google.com/github/luisosmx/crash-course-on-python/blob/main/Errors_and_Exceptions.ipynb\" target=\"_parent\"><img src=\"https://colab.research.google.com/assets/colab-badge.svg\" alt=\"Open In Colab\"/></a>"
      ]
    },
    {
      "cell_type": "markdown",
      "source": [
        "##Practice Notebook - Errors and Exceptions\n",
        "\n",
        "Below we have a function that removes an item from an input list. Run it to see what it does."
      ],
      "metadata": {
        "id": "fTyJIU6v2NYC"
      }
    },
    {
      "cell_type": "code",
      "execution_count": 1,
      "metadata": {
        "colab": {
          "base_uri": "https://localhost:8080/"
        },
        "id": "xL1MAgO72MtS",
        "outputId": "b0b696ac-ec4c-4718-d78f-0860d4ff3d1d"
      },
      "outputs": [
        {
          "output_type": "stream",
          "name": "stdout",
          "text": [
            "[5, 9, 6, 8]\n"
          ]
        }
      ],
      "source": [
        "my_list = [27, 5, 9, 6, 8]\n",
        "\n",
        "def RemoveValue(myVal):\n",
        "    my_list.remove(myVal)\n",
        "    return my_list\n",
        "\n",
        "print(RemoveValue(27))"
      ]
    },
    {
      "cell_type": "markdown",
      "source": [
        "We used the RemoveValue() function to remove the number, 27 from the given list. Great! The function seems to be working fine. However, there is a problem when we try to call the function on the number 27 again. Run the following cell to see what happens."
      ],
      "metadata": {
        "id": "6TDp7BIM2mpJ"
      }
    },
    {
      "cell_type": "code",
      "source": [
        "print(RemoveValue(27))"
      ],
      "metadata": {
        "colab": {
          "base_uri": "https://localhost:8080/",
          "height": 287
        },
        "id": "pAj_NL0q2mHt",
        "outputId": "647e19be-3985-48ef-fab0-e3889e5a67c9"
      },
      "execution_count": 2,
      "outputs": [
        {
          "output_type": "error",
          "ename": "ValueError",
          "evalue": "ignored",
          "traceback": [
            "\u001b[0;31m---------------------------------------------------------------------------\u001b[0m",
            "\u001b[0;31mValueError\u001b[0m                                Traceback (most recent call last)",
            "\u001b[0;32m<ipython-input-2-3f8c37f416f6>\u001b[0m in \u001b[0;36m<cell line: 1>\u001b[0;34m()\u001b[0m\n\u001b[0;32m----> 1\u001b[0;31m \u001b[0mprint\u001b[0m\u001b[0;34m(\u001b[0m\u001b[0mRemoveValue\u001b[0m\u001b[0;34m(\u001b[0m\u001b[0;36m27\u001b[0m\u001b[0;34m)\u001b[0m\u001b[0;34m)\u001b[0m\u001b[0;34m\u001b[0m\u001b[0;34m\u001b[0m\u001b[0m\n\u001b[0m",
            "\u001b[0;32m<ipython-input-1-597531fc6dcc>\u001b[0m in \u001b[0;36mRemoveValue\u001b[0;34m(myVal)\u001b[0m\n\u001b[1;32m      2\u001b[0m \u001b[0;34m\u001b[0m\u001b[0m\n\u001b[1;32m      3\u001b[0m \u001b[0;32mdef\u001b[0m \u001b[0mRemoveValue\u001b[0m\u001b[0;34m(\u001b[0m\u001b[0mmyVal\u001b[0m\u001b[0;34m)\u001b[0m\u001b[0;34m:\u001b[0m\u001b[0;34m\u001b[0m\u001b[0;34m\u001b[0m\u001b[0m\n\u001b[0;32m----> 4\u001b[0;31m     \u001b[0mmy_list\u001b[0m\u001b[0;34m.\u001b[0m\u001b[0mremove\u001b[0m\u001b[0;34m(\u001b[0m\u001b[0mmyVal\u001b[0m\u001b[0;34m)\u001b[0m\u001b[0;34m\u001b[0m\u001b[0;34m\u001b[0m\u001b[0m\n\u001b[0m\u001b[1;32m      5\u001b[0m     \u001b[0;32mreturn\u001b[0m \u001b[0mmy_list\u001b[0m\u001b[0;34m\u001b[0m\u001b[0;34m\u001b[0m\u001b[0m\n\u001b[1;32m      6\u001b[0m \u001b[0;34m\u001b[0m\u001b[0m\n",
            "\u001b[0;31mValueError\u001b[0m: list.remove(x): x not in list"
          ]
        }
      ]
    },
    {
      "cell_type": "markdown",
      "source": [
        "From the above output we see that our function now raises a `ValueError`. This is because we are trying to remove a number from a list that is not in the list. When we removed 27 from the list the first time, it was no longer available in the list to be removed a second time. Python is letting us know that the number 27 no longer makes sense for our RemoveValue() function.\n",
        "\n",
        "We'd like to take control of the error messaging here and pre-empt this error. Fill in the blanks below to raise a ValueError in the RemoveValue() function if a value is not in the list. You can have the error message say something obvious like \"Value must be in the given list\"."
      ],
      "metadata": {
        "id": "ymXydXs72uCr"
      }
    },
    {
      "cell_type": "code",
      "source": [
        "def RemoveValue(myVal):\n",
        "    if myVal not in my_list:\n",
        "        raise ValueError('Value must be in the given list')\n",
        "    else:\n",
        "        my_list.remove(myVal)\n",
        "    return my_list\n",
        "\n",
        "print(RemoveValue(27))"
      ],
      "metadata": {
        "colab": {
          "base_uri": "https://localhost:8080/",
          "height": 321
        },
        "id": "M4KfgIav2W13",
        "outputId": "ebd5f840-02a9-46c5-8621-e19dadb1972e"
      },
      "execution_count": 3,
      "outputs": [
        {
          "output_type": "error",
          "ename": "ValueError",
          "evalue": "ignored",
          "traceback": [
            "\u001b[0;31m---------------------------------------------------------------------------\u001b[0m",
            "\u001b[0;31mValueError\u001b[0m                                Traceback (most recent call last)",
            "\u001b[0;32m<ipython-input-3-17c39a180301>\u001b[0m in \u001b[0;36m<cell line: 8>\u001b[0;34m()\u001b[0m\n\u001b[1;32m      6\u001b[0m     \u001b[0;32mreturn\u001b[0m \u001b[0mmy_list\u001b[0m\u001b[0;34m\u001b[0m\u001b[0;34m\u001b[0m\u001b[0m\n\u001b[1;32m      7\u001b[0m \u001b[0;34m\u001b[0m\u001b[0m\n\u001b[0;32m----> 8\u001b[0;31m \u001b[0mprint\u001b[0m\u001b[0;34m(\u001b[0m\u001b[0mRemoveValue\u001b[0m\u001b[0;34m(\u001b[0m\u001b[0;36m27\u001b[0m\u001b[0;34m)\u001b[0m\u001b[0;34m)\u001b[0m\u001b[0;34m\u001b[0m\u001b[0;34m\u001b[0m\u001b[0m\n\u001b[0m",
            "\u001b[0;32m<ipython-input-3-17c39a180301>\u001b[0m in \u001b[0;36mRemoveValue\u001b[0;34m(myVal)\u001b[0m\n\u001b[1;32m      1\u001b[0m \u001b[0;32mdef\u001b[0m \u001b[0mRemoveValue\u001b[0m\u001b[0;34m(\u001b[0m\u001b[0mmyVal\u001b[0m\u001b[0;34m)\u001b[0m\u001b[0;34m:\u001b[0m\u001b[0;34m\u001b[0m\u001b[0;34m\u001b[0m\u001b[0m\n\u001b[1;32m      2\u001b[0m     \u001b[0;32mif\u001b[0m \u001b[0mmyVal\u001b[0m \u001b[0;32mnot\u001b[0m \u001b[0;32min\u001b[0m \u001b[0mmy_list\u001b[0m\u001b[0;34m:\u001b[0m\u001b[0;34m\u001b[0m\u001b[0;34m\u001b[0m\u001b[0m\n\u001b[0;32m----> 3\u001b[0;31m         \u001b[0;32mraise\u001b[0m \u001b[0mValueError\u001b[0m\u001b[0;34m(\u001b[0m\u001b[0;34m'Value must be in the given list'\u001b[0m\u001b[0;34m)\u001b[0m\u001b[0;34m\u001b[0m\u001b[0;34m\u001b[0m\u001b[0m\n\u001b[0m\u001b[1;32m      4\u001b[0m     \u001b[0;32melse\u001b[0m\u001b[0;34m:\u001b[0m\u001b[0;34m\u001b[0m\u001b[0;34m\u001b[0m\u001b[0m\n\u001b[1;32m      5\u001b[0m         \u001b[0mmy_list\u001b[0m\u001b[0;34m.\u001b[0m\u001b[0mremove\u001b[0m\u001b[0;34m(\u001b[0m\u001b[0mmyVal\u001b[0m\u001b[0;34m)\u001b[0m\u001b[0;34m\u001b[0m\u001b[0;34m\u001b[0m\u001b[0m\n",
            "\u001b[0;31mValueError\u001b[0m: Value must be in the given list"
          ]
        }
      ]
    },
    {
      "cell_type": "markdown",
      "source": [
        "Did your error message print correctly? Was the output something like: `ValueError`: Value must be in the given list? If not, go back to the previous cell and make sure you filled in the blanks correctly. If your error message did print correctly, great! You are on your way to mastering the basics of handling errors and exceptions.\n",
        "\n",
        "Now, let's look at a different function. Below we have a function that sorts an input list alphabetically. Run it to see what it does"
      ],
      "metadata": {
        "id": "VYep86Oq26v8"
      }
    },
    {
      "cell_type": "code",
      "source": [
        "my_word_list = ['east', 'after', 'up', 'over', 'inside']\n",
        "\n",
        "def OrganizeList(myList):\n",
        "    myList.sort()\n",
        "    return myList\n",
        "\n",
        "print(OrganizeList(my_word_list))"
      ],
      "metadata": {
        "colab": {
          "base_uri": "https://localhost:8080/"
        },
        "id": "rkzUr-_b23aN",
        "outputId": "dbfea639-067e-4ac9-e220-7b272c99aaf1"
      },
      "execution_count": 4,
      "outputs": [
        {
          "output_type": "stream",
          "name": "stdout",
          "text": [
            "['after', 'east', 'inside', 'over', 'up']\n"
          ]
        }
      ]
    },
    {
      "cell_type": "markdown",
      "source": [
        "We used the OrganizeList() function to sort a given list alphabetically. The function seems to be working fine. However, there is a problem when we try to call the function on a list containing number values. Run the following cell to see what happens."
      ],
      "metadata": {
        "id": "vsXvBtuI3EID"
      }
    },
    {
      "cell_type": "code",
      "source": [
        "my_new_list = [6, 3, 8, \"12\", 42]\n",
        "print(OrganizeList(my_new_list))"
      ],
      "metadata": {
        "colab": {
          "base_uri": "https://localhost:8080/",
          "height": 304
        },
        "id": "N_d7m5eL3BOJ",
        "outputId": "bcb28290-8e38-44c5-eab1-3e114761b1db"
      },
      "execution_count": 5,
      "outputs": [
        {
          "output_type": "error",
          "ename": "TypeError",
          "evalue": "ignored",
          "traceback": [
            "\u001b[0;31m---------------------------------------------------------------------------\u001b[0m",
            "\u001b[0;31mTypeError\u001b[0m                                 Traceback (most recent call last)",
            "\u001b[0;32m<ipython-input-5-459d95f39adf>\u001b[0m in \u001b[0;36m<cell line: 2>\u001b[0;34m()\u001b[0m\n\u001b[1;32m      1\u001b[0m \u001b[0mmy_new_list\u001b[0m \u001b[0;34m=\u001b[0m \u001b[0;34m[\u001b[0m\u001b[0;36m6\u001b[0m\u001b[0;34m,\u001b[0m \u001b[0;36m3\u001b[0m\u001b[0;34m,\u001b[0m \u001b[0;36m8\u001b[0m\u001b[0;34m,\u001b[0m \u001b[0;34m\"12\"\u001b[0m\u001b[0;34m,\u001b[0m \u001b[0;36m42\u001b[0m\u001b[0;34m]\u001b[0m\u001b[0;34m\u001b[0m\u001b[0;34m\u001b[0m\u001b[0m\n\u001b[0;32m----> 2\u001b[0;31m \u001b[0mprint\u001b[0m\u001b[0;34m(\u001b[0m\u001b[0mOrganizeList\u001b[0m\u001b[0;34m(\u001b[0m\u001b[0mmy_new_list\u001b[0m\u001b[0;34m)\u001b[0m\u001b[0;34m)\u001b[0m\u001b[0;34m\u001b[0m\u001b[0;34m\u001b[0m\u001b[0m\n\u001b[0m",
            "\u001b[0;32m<ipython-input-4-252da45e411d>\u001b[0m in \u001b[0;36mOrganizeList\u001b[0;34m(myList)\u001b[0m\n\u001b[1;32m      2\u001b[0m \u001b[0;34m\u001b[0m\u001b[0m\n\u001b[1;32m      3\u001b[0m \u001b[0;32mdef\u001b[0m \u001b[0mOrganizeList\u001b[0m\u001b[0;34m(\u001b[0m\u001b[0mmyList\u001b[0m\u001b[0;34m)\u001b[0m\u001b[0;34m:\u001b[0m\u001b[0;34m\u001b[0m\u001b[0;34m\u001b[0m\u001b[0m\n\u001b[0;32m----> 4\u001b[0;31m     \u001b[0mmyList\u001b[0m\u001b[0;34m.\u001b[0m\u001b[0msort\u001b[0m\u001b[0;34m(\u001b[0m\u001b[0;34m)\u001b[0m\u001b[0;34m\u001b[0m\u001b[0;34m\u001b[0m\u001b[0m\n\u001b[0m\u001b[1;32m      5\u001b[0m     \u001b[0;32mreturn\u001b[0m \u001b[0mmyList\u001b[0m\u001b[0;34m\u001b[0m\u001b[0;34m\u001b[0m\u001b[0m\n\u001b[1;32m      6\u001b[0m \u001b[0;34m\u001b[0m\u001b[0m\n",
            "\u001b[0;31mTypeError\u001b[0m: '<' not supported between instances of 'str' and 'int'"
          ]
        }
      ]
    },
    {
      "cell_type": "markdown",
      "source": [
        "From the above output we see that our function now raises a `TypeError`. This is because the OrganizeList() function makes sense for lists that are filled with only strings. Take control of the error messaging here and pre-empt this error by filling in the blanks below to add an assert type argument that verifies whether the input list is filled with only strings. You can have the error message say something like \"Word list must be a list of strings\"."
      ],
      "metadata": {
        "id": "tEN6h8Ag3LqL"
      }
    },
    {
      "cell_type": "code",
      "source": [
        "def OrganizeList(myList):\n",
        "    for item in myList:\n",
        "        assert type(myList)==str, ' Word list must be a list of strings'\n",
        "    myList.sort()\n",
        "    return myList\n",
        "\n",
        "print(OrganizeList(my_new_list))"
      ],
      "metadata": {
        "colab": {
          "base_uri": "https://localhost:8080/",
          "height": 321
        },
        "id": "fTX9fc8-3Hg5",
        "outputId": "caa095c9-714f-4cfd-e0c0-00b010768d0e"
      },
      "execution_count": 6,
      "outputs": [
        {
          "output_type": "error",
          "ename": "AssertionError",
          "evalue": "ignored",
          "traceback": [
            "\u001b[0;31m---------------------------------------------------------------------------\u001b[0m",
            "\u001b[0;31mAssertionError\u001b[0m                            Traceback (most recent call last)",
            "\u001b[0;32m<ipython-input-6-fc474ebe4823>\u001b[0m in \u001b[0;36m<cell line: 7>\u001b[0;34m()\u001b[0m\n\u001b[1;32m      5\u001b[0m     \u001b[0;32mreturn\u001b[0m \u001b[0mmyList\u001b[0m\u001b[0;34m\u001b[0m\u001b[0;34m\u001b[0m\u001b[0m\n\u001b[1;32m      6\u001b[0m \u001b[0;34m\u001b[0m\u001b[0m\n\u001b[0;32m----> 7\u001b[0;31m \u001b[0mprint\u001b[0m\u001b[0;34m(\u001b[0m\u001b[0mOrganizeList\u001b[0m\u001b[0;34m(\u001b[0m\u001b[0mmy_new_list\u001b[0m\u001b[0;34m)\u001b[0m\u001b[0;34m)\u001b[0m\u001b[0;34m\u001b[0m\u001b[0;34m\u001b[0m\u001b[0m\n\u001b[0m",
            "\u001b[0;32m<ipython-input-6-fc474ebe4823>\u001b[0m in \u001b[0;36mOrganizeList\u001b[0;34m(myList)\u001b[0m\n\u001b[1;32m      1\u001b[0m \u001b[0;32mdef\u001b[0m \u001b[0mOrganizeList\u001b[0m\u001b[0;34m(\u001b[0m\u001b[0mmyList\u001b[0m\u001b[0;34m)\u001b[0m\u001b[0;34m:\u001b[0m\u001b[0;34m\u001b[0m\u001b[0;34m\u001b[0m\u001b[0m\n\u001b[1;32m      2\u001b[0m     \u001b[0;32mfor\u001b[0m \u001b[0mitem\u001b[0m \u001b[0;32min\u001b[0m \u001b[0mmyList\u001b[0m\u001b[0;34m:\u001b[0m\u001b[0;34m\u001b[0m\u001b[0;34m\u001b[0m\u001b[0m\n\u001b[0;32m----> 3\u001b[0;31m         \u001b[0;32massert\u001b[0m \u001b[0mtype\u001b[0m\u001b[0;34m(\u001b[0m\u001b[0mmyList\u001b[0m\u001b[0;34m)\u001b[0m\u001b[0;34m==\u001b[0m\u001b[0mstr\u001b[0m\u001b[0;34m,\u001b[0m \u001b[0;34m' Word list must be a list of strings'\u001b[0m\u001b[0;34m\u001b[0m\u001b[0;34m\u001b[0m\u001b[0m\n\u001b[0m\u001b[1;32m      4\u001b[0m     \u001b[0mmyList\u001b[0m\u001b[0;34m.\u001b[0m\u001b[0msort\u001b[0m\u001b[0;34m(\u001b[0m\u001b[0;34m)\u001b[0m\u001b[0;34m\u001b[0m\u001b[0;34m\u001b[0m\u001b[0m\n\u001b[1;32m      5\u001b[0m     \u001b[0;32mreturn\u001b[0m \u001b[0mmyList\u001b[0m\u001b[0;34m\u001b[0m\u001b[0;34m\u001b[0m\u001b[0m\n",
            "\u001b[0;31mAssertionError\u001b[0m:  Word list must be a list of strings"
          ]
        }
      ]
    },
    {
      "cell_type": "markdown",
      "source": [
        "Did your error message print correctly? Was the output something like: `AssertionError`: Word list must be a list of strings? If not, go back to the previous cell and make sure you filled in the blanks correctly. If your error message did print correctly, excellent! You are another step closer to mastering the basics of handling errors and exceptions.\n",
        "\n",
        "Let's look at one last code block. The Guess() function below takes a list of participants, assigns each a random number from 1 to 9, and stores this information in a dictionary with the participant name as the key. It then returns True if Larry was assigned the number 9 and False if this was not the case. Run it to see what it does."
      ],
      "metadata": {
        "id": "gG4gX-8V3T07"
      }
    },
    {
      "cell_type": "code",
      "source": [
        "import random\n",
        "\n",
        "participants = ['Jack','Jill','Larry','Tom']\n",
        "\n",
        "def Guess(participants):\n",
        "    my_participant_dict = {}\n",
        "    for participant in participants:\n",
        "        my_participant_dict[participant] = random.randint(1, 9)\n",
        "    if my_participant_dict['Larry'] == 9:\n",
        "        return True\n",
        "    else:\n",
        "        return False\n",
        "    \n",
        "print(Guess(participants))"
      ],
      "metadata": {
        "colab": {
          "base_uri": "https://localhost:8080/"
        },
        "id": "eFCT0dfT3QXp",
        "outputId": "145ca958-01b7-415d-9c03-aa3ec9fba4b4"
      },
      "execution_count": 7,
      "outputs": [
        {
          "output_type": "stream",
          "name": "stdout",
          "text": [
            "False\n"
          ]
        }
      ]
    },
    {
      "cell_type": "markdown",
      "source": [
        "The code seems to be working fine.  However, there are some things that could go wrong, so find the part that might throw an exception and wrap it in a try-except block to ensure that you get sensible behavior.  Do this in the cell below. Code your function to return *None* if an exception occurs."
      ],
      "metadata": {
        "id": "4dsM1OAa3cQ6"
      }
    },
    {
      "cell_type": "code",
      "source": [
        "# Revised Guess() function\n",
        "def Guess(participants):\n",
        "    my_participant_dict = {}\n",
        "    for participant in participants:\n",
        "        my_participant_dict[participant] = random.randint(1, 9)\n",
        "        try:\n",
        "            f = open(participants)\n",
        "            if my_participant_dict['Larry'] == 9:\n",
        "                return True\n",
        "            else:\n",
        "                return False\n",
        "        except TypeError:\n",
        "                return None"
      ],
      "metadata": {
        "id": "vFmbjPlh3YnL"
      },
      "execution_count": 8,
      "outputs": []
    },
    {
      "cell_type": "markdown",
      "source": [
        "Call your revised Guess() function with the following participant list."
      ],
      "metadata": {
        "id": "wcxLaJzP3jT5"
      }
    },
    {
      "cell_type": "code",
      "source": [
        "participants = ['Cathy','Fred','Jack','Tom']\n",
        "print(Guess(participants))"
      ],
      "metadata": {
        "colab": {
          "base_uri": "https://localhost:8080/"
        },
        "id": "MEWC-yNX3g8m",
        "outputId": "e7790c9d-7653-4d23-9449-c3746fa22745"
      },
      "execution_count": 9,
      "outputs": [
        {
          "output_type": "stream",
          "name": "stdout",
          "text": [
            "None\n"
          ]
        }
      ]
    },
    {
      "cell_type": "markdown",
      "source": [
        "Was the above output None? If not, go back to the code block containing your revised Guess() function and make edits so that the output is None for the previous code block. If the above output was indeed None, congratulations! You've mastered the basics of handling errors and exceptions in Python and you are all done with this notebook!"
      ],
      "metadata": {
        "id": "R3W1ky453sOh"
      }
    }
  ]
}